Workbook

Sheet 📋 DATOS
B2: AETERION
B3: SISTEMA DE ENTRENAMIENTO — GYM GENERAL · HIPERTROFIA
B4: Ciencia. Disciplina. Resultados.
B6: ① PERFIL FÍSICO — Completa los campos amarillos
B7: Nombre | D7: Edad (años) | F7: Peso (kg) | H7: Estatura (cm) | J7: Sexo | L7: % Grasa corporal
B8: Tu nombre | D8: 25 | F8: 75 | H8: 170 | J8: H | L8: 18
B9: ↓ Calculado | D9: IMC | E9: =IF(D8>0,C8/(D8/100)^2,"") -> 0 | G9: Masa magra kg | H9: =IF(F8>0,C8*(1-F8/100),"") -> 0 | J9: Cat. IMC | K9: =IF(E9<18.5,"Bajo peso",IF(E9<25,"Normal",IF(E9<30,"Sobrepeso","Obesidad"))) -> Bajo peso
B11: ② NIVEL REAL — Responde con honestidad para un plan preciso
B12: Tiempo entrenando | D12: Banca 5-8 reps (kg) | F12: Sentadilla 5-8 reps (kg) | H12: P.Muerto 5-8 reps (kg) | J12: Dominadas (reps)
B13: 6–24 meses | D13: 60 | F13: 80 | H13: 100 | J13: 5
B14: 1RM estimado (Epley): | D14: Banca | E14: =IF(D13>0,ROUND(D13*(1+8/30),0),"") -> 76 | G14: Sentadilla | H14: =IF(F13>0,ROUND(F13*(1+8/30),0),"") -> 101 | J14: P.Muerto | K14: =IF(H13>0,ROUND(H13*(1+8/30),0),"") -> 127
B15: Nivel detectado: | D15: =IF(C13="Menos de 6 meses","⬤ PRINCIPIANTE",IF(C13="6–24 meses","⬤ PRINCIPIANTE-INTERMEDIO",IF(C13="2–4 años","⬤ INTERMEDIO","⬤ AVANZADO"))) -> ⬤ AVANZADO | I15: =IF(C13="Menos de 6 meses","Periodización lineal — añadir peso cada sesión",IF(C13="6–24 meses","Lineal → doble progresión",IF(C13="2–4 años","DUP — Ondulante diaria (Colquhoun 2017)","Bloques (Bompa & Haff)"))) -> Bloques (Bompa & Haff)
B17: ③ OBJETIVO — Hipertrofia como base. Selecciona variante
B18: Variante principal | F18: Secundario | J18: Rutina seleccionada
B19: Hipertrofia pura | F19: Pérdida de grasa | J19: Hombre 5 días
B21: ④ HÁBITOS — Determinan el volumen real que puedes absorber
B22: Sueño (h) | D22: Estrés | F22: Trabajo | H22: Alimentación | J22: Hidratación | L22: Proteína/día
B23: 7 | D23: Medio | F23: Sedentario | H23: Regular | J23: Regular 1.5-2L | L23: Media 1-1.5g/kg
B24: Modificador volumen: | D24: =MAX(0.6,MIN(1.15,1+IF(C23<=6,-0.15,0)+IF(E23="Alto",-0.15,0)+IF(G23="Físico intenso",-0.1,0)+IF(I23="Mala",-0.1,IF(I23="Óptima",0.05,0))+IF(M23="Baja <1g/kg",-0.1,IF(M23="Óptima 2g/kg+",0.05,0)))) -> 0.85 | G24: ← 100% = hábitos óptimos. Sueño ≤6h = −15%. Estrés alto = −15%. Trabajo físico = −10%.
B26: ⑤ DISPONIBILIDAD
B27: Días/semana | F27: Duración sesión | J27: Equipamiento
B28: 5 | F28: 60–90 min | J28: Gimnasio completo

Sheet 🔴 H-5 DÍAS
B2: RUTINA HOMBRE — 5 DÍAS DE ESTÍMULO
B3: Hipertrofia · Push/Pull/Legs + Upper + Legs&Arms · Periodización DUP
B5: MODELO DE SEMANA: Día 1 Push · Día 2 Pull · Día 3 Piernas · Día 4 Descanso · Día 5 Upper Full · Día 6 Piernas+Brazos · Día 7 Descanso
B7: DÍA 1 — PUSH (2 Pecho · 2 Hombro · 2 Tríceps)
B8: HIPERTROFIA · RPE 7–8 · Doble progresión
B9: # | C9: Ejercicio | D9: Músculo | E9: Series | F9: Reps | G9: Descanso | H9: RPE | I9: Nota técnica / Carga
B10: 1 | C10: Press inclinado con barra/mancuerna | D10: Pecho alto | E10: 3–4 | F10: 8–12 | G10: 90–120s | H10: RPE 8 | I10: Ejercicio principal. Escápulas retraídas. Foco: aleja la barra del techo.
B11: 2 | C11: Pec fly / Aperturas con mancuerna | D11: Pecho medio | E11: 3 | F11: 12–15 | G11: 60–75s | H11: RPE 7 | I11: Accesorio. Estiramiento máximo en excéntrica. Controla la bajada.
B12: 3 | C12: Press militar con mancuernas (sentado) | D12: Deltoides ant/med | E12: 3–4 | F12: 8–12 | G12: 90s | H12: RPE 8 | I12: Core activo. Sin hiperlordosis. Codos a 45° del cuerpo.
B13: 4 | C13: Elevaciones laterales con mancuernas | D13: Deltoides medio | E13: 3–4 | F13: 12–20 | G13: 45–60s | H13: RPE 7 | I13: No balancear. Meñique arriba. Ligero adelanto del torso.
B14: 5 | C14: Extensión de tríceps unilateral en polea | D14: Tríceps | E14: 3 | F14: 10–15 | G14: 60s | H14: RPE 7 | I14: Codo fijo al costado. Solo mueve el antebrazo. Contracción completa.
B15: 6 | C15: Press francés / JM Press | D15: Tríceps cabeza larga | E15: 3 | F15: 10–12 | G15: 75s | H15: RPE 7–8 | I15: Codos al techo. No abrir hacia los lados. Rango completo.
B16: ↑ Progresión (doble progresión): completa el tope del rango de reps en TODAS las series → sube 2.5kg (comp.) o 1-2kg (accesorio). Vuelve al rango bajo con la nueva carga.
B18: DÍA 2 — PULL (3 Espalda · 1 Deltoides posterior · 2 Bíceps)
B19: HIPERTROFIA · RPE 7–8 · Doble progresión
B20: # | C20: Ejercicio | D20: Músculo | E20: Series | F20: Reps | G20: Descanso | H20: RPE | I20: Nota técnica / Carga
B21: 1 | C21: Jalón al pecho | D21: Dorsal ancho | E21: 3–4 | F21: 8–12 | G21: 90s | H21: RPE 8 | I21: Foco externo: jala la barra hacia tu cintura. Pecho abierto.
B22: 2 | C22: Remo en T | D22: Dorsal / Romboides | E22: 3–4 | F22: 8–12 | G22: 90–120s | H22: RPE 8 | I22: Pecho apoyado. Pausa 1s al contraer. Escápulas al final.
B23: 3 | C23: Remo horizontal en máquina | D23: Trapecio medio | E23: 3 | F23: 10–12 | G23: 75s | H23: RPE 7 | I23: Pausa 1s. Codos hacia atrás. Retracción escapular completa.
B24: 4 | C24: Aperturas inversas en máquina | D24: Deltoides posterior | E24: 3 | F24: 12–15 | G24: 60s | H24: RPE 7 | I24: Pecho apoyado. Movimiento desde el hombro. No del codo.
B25: 5 | C25: Curl Bayesian en polea | D25: Bíceps (estiramiento) | E25: 3 | F25: 10–15 | G25: 60s | H25: RPE 7 | I25: Posición de estiramiento máximo del bíceps. Supina al contraer.
B26: 6 | C26: Curl martillo | D26: Braquialis / Braquiorradial | E26: 3 | F26: 10–15 | G26: 60s | H26: RPE 7 | I26: Agarre neutro. Trabaja braquialis. No balancear el torso.
B27: ↑ Progresión (doble progresión): completa el tope del rango de reps en TODAS las series → sube 2.5kg (comp.) o 1-2kg (accesorio). Vuelve al rango bajo con la nueva carga.
B29: DÍA 3 — PIERNAS (2 Compuestos · 2 Aislamiento · 1 Glúteo · 2 Pantorrilla)
B30: HIPERTROFIA · RPE 7–8 · Doble progresión
B31: # | C31: Ejercicio | D31: Músculo | E31: Series | F31: Reps | G31: Descanso | H31: RPE | I31: Nota técnica / Carga
B32: 1 | C32: Sentadilla Smith / Hack / Prensa | D32: Cuádriceps | E32: 4 | F32: 8–12 | G32: 2–3 min | H32: RPE 8 | I32: Compuesto principal. Empuja el suelo lejos de ti. Rango completo.
B33: 2 | C33: Peso muerto rumano | D33: Glúteo / Isquiotibiales | E33: 3–4 | F33: 10–12 | G33: 90–120s | H33: RPE 8 | I33: Compuesto. Excéntrico 3–4s. Isquiotibiales al límite. Espalda neutra.
B34: 3 | C34: Extensión de cuádriceps en máquina | D34: Cuádriceps aislado | E34: 3 | F34: 12–15 | G34: 60s | H34: RPE 7 | I34: Aislamiento. Pausa 1s en extensión completa. Contracción máxima.
B35: 4 | C35: Curl femoral tumbado/sentado | D35: Isquiotibiales | E35: 3 | F35: 10–15 | G35: 60–75s | H35: RPE 7 | I35: Aislamiento. Cadera apoyada. Rango de movimiento completo.
B36: 5 | C36: Hip thrust con barra | D36: Glúteo mayor | E36: 3 | F36: 10–12 | G36: 90s | H36: RPE 8 | I36: Glúteo dominante. Pausa 2s arriba. Empuje desde el talón.
B37: 6 | C37: Elevación de talón de pie | D37: Gastrocnemio | E37: 4 | F37: 12–15 | G37: 45–60s | H37: RPE 7 | I37: Rango completo. Pausa 1s arriba y abajo. No rebotar.
B38: 7 | C38: Elevación de talón sentado | D38: Sóleo | E38: 3 | F38: 15–20 | G38: 45s | H38: RPE 7 | I38: Sóleo. Rango completo. Pausa abajo para estiramiento.
B39: ↑ Progresión (doble progresión): completa el tope del rango de reps en TODAS las series → sube 2.5kg (comp.) o 1-2kg (accesorio). Vuelve al rango bajo con la nueva carga.
B41: DÍA 4 — DESCANSO ACTIVO · Movilidad 10–15 min + hidratación + sueño prioritario
B43: DÍA 5 — FULL UPPER (2 Pecho · 2 Espalda · 2 Hombro)
B44: HIPERTROFIA · RPE 7 · Segundo estímulo semanal
B45: # | C45: Ejercicio | D45: Músculo | E45: Series | F45: Reps | G45: Descanso | H45: RPE | I45: Nota técnica / Carga
B46: 1 | C46: Press inclinado con mancuerna | D46: Pecho alto | E46: 3 | F46: 10–12 | G46: 90s | H46: RPE 7–8 | I46: Variante del día 1. Peso ligeramente menor. Rango completo.
B47: 2 | C47: Aperturas en máquina (pec deck) | D47: Pecho medio | E47: 3 | F47: 12–15 | G47: 60s | H47: RPE 7 | I47: Pec deck. Estiramiento máximo. Contracción lenta.
...

Sheet 🟡 H-3 DÍAS
B2: RUTINA HOMBRE — 3 DÍAS DE ESTÍMULO
B3: Hipertrofia · Full Body + Superior + Inferior · Progresión lineal
B5: MODELO DE SEMANA: Día 1 Cuerpo completo · Día 2 Descanso · Día 3 Superior · Día 4 Descanso · Día 5 Inferior · Días 6–7 Descanso
B7: DÍA 1 — CUERPO COMPLETO
B8: HIPERTROFIA · Compuestos prioritarios · RPE 7–8
B9: # | C9: Ejercicio | D9: Músculo | E9: Series | F9: Reps | G9: Descanso | H9: RPE | I9: Nota técnica / Carga
B10: 1 | C10: Sentadilla Smith / Hack / Prensa | D10: Cuádriceps | E10: 3 | F10: 8–10 | G10: 2 min | H10: RPE 7–8 | I10: Compuesto pierna. Base de la sesión. Foco: empuja el suelo.
B11: 2 | C11: Press inclinado con barra/mancuerna | D11: Pecho alto | E11: 3 | F11: 8–10 | G11: 90s | H11: RPE 8 | I11: Compuesto pecho. Escápulas retraídas. Foco: aleja la barra del techo.
B12: 3 | C12: Jalón al pecho | D12: Dorsal ancho | E12: 3 | F12: 8–10 | G12: 90s | H12: RPE 8 | I12: Compuesto espalda. Foco externo: jala hacia tu cintura.
B13: 4 | C13: Press militar con mancuernas (sentado) | D13: Deltoides | E13: 3 | F13: 10–12 | G13: 90s | H13: RPE 7 | I13: Hombro. Core activo. Codos a 45°.
B14: 5 | C14: Hip thrust con barra | D14: Glúteo mayor | E14: 3 | F14: 10–12 | G14: 90s | H14: RPE 7–8 | I14: Glúteo. Pausa 2s arriba. Empuje desde el talón.
B15: 6 | C15: Curl en polea / barra | D15: Bíceps | E15: 2 | F15: 10–12 | G15: 60s | H15: RPE 7 | I15: Bíceps. Supinación completa. No balancear.
B16: 7 | C16: Extensión de tríceps unilateral en polea | D16: Tríceps | E16: 2 | F16: 10–12 | G16: 60s | H16: RPE 7 | I16: Tríceps. Codo fijo. Contracción completa.
B17: ↑ Progresión (doble progresión): completa el tope del rango de reps en TODAS las series → sube 2.5kg (comp.) o 1-2kg (accesorio). Vuelve al rango bajo con la nueva carga.
B19: DÍA 2 — DESCANSO
B21: DÍA 3 — SUPERIOR
B22: HIPERTROFIA · Tren superior completo · RPE 7–8
B23: # | C23: Ejercicio | D23: Músculo | E23: Series | F23: Reps | G23: Descanso | H23: RPE | I23: Nota técnica / Carga
B24: 1 | C24: Press inclinado con mancuerna | D24: Pecho alto | E24: 3–4 | F24: 10–12 | G24: 90s | H24: RPE 8 | I24: Segundo estímulo pecho. Variante con mancuerna para mayor rango.
B25: 2 | C25: Pec fly / Aperturas | D25: Pecho medio | E25: 3 | F25: 12–15 | G25: 60s | H25: RPE 7 | I25: Accesorio pecho. Estiramiento máximo. Controla la bajada.
B26: 3 | C26: Remo en T | D26: Dorsal / Romboides | E26: 3–4 | F26: 10–12 | G26: 90s | H26: RPE 8 | I26: Espalda. Pecho apoyado. Pausa 1s al contraer.
B27: 4 | C27: Elevaciones laterales | D27: Deltoides medio | E27: 3–4 | F27: 12–20 | G27: 45s | H27: RPE 7 | I27: Hombro. No balancear. Alto rango de reps. Contracción voluntaria.
B28: 5 | C28: Aperturas inversas en máquina | D28: Deltoides posterior | E28: 3 | F28: 12–15 | G28: 60s | H28: RPE 7 | I28: Deltoides posterior. Pecho apoyado. Desde el hombro.
B29: 6 | C29: Curl Bayesian en polea | D29: Bíceps | E29: 3 | F29: 10–15 | G29: 60s | H29: RPE 7 | I29: Bíceps en estiramiento. Supinación completa al contraer.
B30: 7 | C30: Press francés / JM Press | D30: Tríceps | E30: 3 | F30: 10–12 | G30: 75s | H30: RPE 7 | I30: Tríceps cabeza larga. Codos al techo. No abrir.
B31: ↑ Progresión (doble progresión): completa el tope del rango de reps en TODAS las series → sube 2.5kg (comp.) o 1-2kg (accesorio). Vuelve al rango bajo con la nueva carga.
B33: DÍA 4 — DESCANSO
B35: DÍA 5 — INFERIOR
B36: HIPERTROFIA · Tren inferior completo · RPE 7–8
B37: # | C37: Ejercicio | D37: Músculo | E37: Series | F37: Reps | G37: Descanso | H37: RPE | I37: Nota técnica / Carga
B38: 1 | C38: Sentadilla búlgara | D38: Glúteo / Cuádriceps | E38: 4 | F38: 10–12 | G38: 90s | H38: RPE 8 | I38: Compuesto dominante. Pie trasero en banco. Rodilla no pasa el pie.
B39: 2 | C39: Peso muerto rumano | D39: Glúteo / Isquiotibiales | E39: 3 | F39: 10–12 | G39: 90–120s | H39: RPE 8 | I39: Cadena posterior. Excéntrico 3–4s. Espalda neutra.
B40: 3 | C40: Extensión de cuádriceps | D40: Cuádriceps aislado | E40: 3 | F40: 12–15 | G40: 60s | H40: RPE 7 | I40: Aislamiento. Pausa 1s arriba. Contracción máxima.
B41: 4 | C41: Curl femoral | D41: Isquiotibiales | E41: 3 | F41: 12–15 | G41: 60s | H41: RPE 7 | I41: Aislamiento. Cadera apoyada. Rango completo.
B42: 5 | C42: Hip thrust con barra | D42: Glúteo mayor | E42: 3 | F42: 12–15 | G42: 75s | H42: RPE 7 | I42: Glúteo. Pausa 2s. Segundo estímulo semanal.
B43: 6 | C43: Elevación de talón de pie | D43: Gastrocnemio | E43: 3 | F43: 12–15 | G43: 45s | H43: RPE 7 | I43: Pantorrilla. Rango completo. No rebotar.
B44: 7 | C44: Elevación de talón sentado | D44: Sóleo | E44: 3 | F44: 15–20 | G44: 45s | H44: RPE 7 | I44: Sóleo. Pausa abajo. Rango completo.
B45: ↑ Progresión (doble progresión): completa el tope del rango de reps en TODAS las series → sube 2.5kg (comp.) o 1-2kg (accesorio). Vuelve al rango bajo con la nueva carga.
B47: DÍAS 6–7 — DESCANSO TOTAL

Sheet 🟣 M-5 DÍAS
B2: RUTINA MUJER — 5 DÍAS DE ESTÍMULO
B3: Hipertrofia · Glúteo dominante · Mayor frecuencia tren inferior
B5: MODELO DE SEMANA: Día 1 Pierna glúteo · Día 2 Tren superior · Día 3 Descanso · Día 4 Pierna cuádriceps · Día 5 Full body énfasis glúteo · Días 6–7 Descanso
B7: DÍA 1 — PIERNA (Glúteo dominante)
B8: HIPERTROFIA · Énfasis glúteo · RPE 7–8
B9: # | C9: Ejercicio | D9: Músculo | E9: Series | F9: Reps | G9: Descanso | H9: RPE | I9: Nota técnica / Carga
B10: 1 | C10: Hip thrust con barra | D10: Glúteo mayor | E10: 4 | F10: 8–12 | G10: 90s | H10: RPE 8 | I10: Principal. Pausa 2s arriba. Contracción glútea máxima. Empuje desde el talón.
B11: 2 | C11: Peso muerto rumano | D11: Glúteo / Isquiotibiales | E11: 3–4 | F11: 10–12 | G11: 90–120s | H11: RPE 8 | I11: Compuesto. Excéntrico 3–4s. Isquiotibiales al límite. Espalda neutra.
B12: 3 | C12: Sentadilla búlgara | D12: Glúteo / Cuádriceps | E12: 3 | F12: 10–12 | G12: 90s | H12: RPE 8 | I12: Glúteo dominante. Pie trasero en banco. Torso ligeramente adelante.
B13: 4 | C13: Patada de glúteo en polea | D13: Glúteo mayor | E13: 3 | F13: 12–15 | G13: 60s | H13: RPE 7 | I13: Aislamiento. Cadera fija. Solo mueve la pierna. Contracción final.
B14: 5 | C14: Abducción en máquina | D14: Glúteo medio | E14: 3 | F14: 15–20 | G14: 45–60s | H14: RPE 7 | I14: Glúteo medio. Movimiento controlado. Pausa 1s al contraer.
B15: 6 | C15: Elevación de talón de pie | D15: Gastrocnemio | E15: 3 | F15: 12–15 | G15: 45s | H15: RPE 7 | I15: Pantorrilla. Rango completo. Pausa 1s arriba y abajo.
B16: ↑ Progresión (doble progresión): completa el tope del rango de reps en TODAS las series → sube 2.5kg (comp.) o 1-2kg (accesorio). Vuelve al rango bajo con la nueva carga.
B18: DÍA 2 — TREN SUPERIOR
B19: HIPERTROFIA · Tren superior completo · RPE 7–8
B20: # | C20: Ejercicio | D20: Músculo | E20: Series | F20: Reps | G20: Descanso | H20: RPE | I20: Nota técnica / Carga
B21: 1 | C21: Press inclinado con mancuerna | D21: Pecho alto | E21: 3 | F21: 10–12 | G21: 90s | H21: RPE 7–8 | I21: Compuesto pecho. Escápulas retraídas. Foco: aleja las mancuernas del techo.
B22: 2 | C22: Pec fly / Aperturas con mancuerna | D22: Pecho medio | E22: 3 | F22: 12–15 | G22: 60s | H22: RPE 7 | I22: Accesorio. Estiramiento máximo en excéntrica. Controla la bajada.
B23: 3 | C23: Jalón al pecho | D23: Dorsal ancho | E23: 3–4 | F23: 10–12 | G23: 90s | H23: RPE 7–8 | I23: Espalda. Foco: jala la barra hacia tu cintura. Pecho abierto.
B24: 4 | C24: Remo horizontal en máquina | D24: Trapecio / Romboides | E24: 3 | F24: 10–12 | G24: 75s | H24: RPE 7 | I24: Espalda media. Pausa 1s. Retracción escapular completa.
B25: 5 | C25: Elevaciones laterales con mancuernas | D25: Deltoides medio | E25: 3–4 | F25: 12–20 | G25: 45s | H25: RPE 7 | I25: Hombro. No balancear. Meñique arriba. Contracción voluntaria.
B26: 6 | C26: Press militar con mancuernas | D26: Deltoides | E26: 3 | F26: 10–12 | G26: 90s | H26: RPE 7 | I26: Hombro. Core activo. Sin hiperlordosis. Codos a 45°.
B27: 7 | C27: Curl en polea / barra | D27: Bíceps | E27: 3 | F27: 10–12 | G27: 60s | H27: RPE 7 | I27: Bíceps. Supinación completa. No balancear el torso.
B28: 8 | C28: Extensión de tríceps en polea | D28: Tríceps | E28: 3 | F28: 12–15 | G28: 60s | H28: RPE 7 | I28: Tríceps. Codo fijo. Contracción completa. Tempo controlado.
B29: ↑ Progresión (doble progresión): completa el tope del rango de reps en TODAS las series → sube 2.5kg (comp.) o 1-2kg (accesorio). Vuelve al rango bajo con la nueva carga.
B31: DÍA 3 — DESCANSO ACTIVO · Movilidad, caminata ligera o yoga. No entrenar con intensidad.
B33: DÍA 4 — PIERNA (Cuádriceps dominante)
B34: HIPERTROFIA · Énfasis cuádriceps · RPE 7–8
B35: # | C35: Ejercicio | D35: Músculo | E35: Series | F35: Reps | G35: Descanso | H35: RPE | I35: Nota técnica / Carga
B36: 1 | C36: Sentadilla Smith / Hack / Prensa | D36: Cuádriceps | E36: 4 | F36: 8–12 | G36: 2–3 min | H36: RPE 8 | I36: Compuesto. Cuádriceps dominante. Foco: empuja el suelo lejos de ti.
B37: 2 | C37: Extensión de cuádriceps en máquina | D37: Cuádriceps aislado | E37: 3 | F37: 12–15 | G37: 60s | H37: RPE 7 | I37: Aislamiento. Pausa 1s en extensión completa. Contracción voluntaria máxima.
B38: 3 | C38: Curl femoral tumbado/sentado | D38: Isquiotibiales | E38: 3 | F38: 10–15 | G38: 60–75s | H38: RPE 7 | I38: Aislamiento. Cadera apoyada. Rango de movimiento completo.
B39: 4 | C39: Zancadas con mancuernas | D39: Cuádriceps / Glúteo | E39: 3 | F39: 10–12/pierna | G39: 75s | H39: RPE 7 | I39: Torso erguido. Rodilla trasera cerca del suelo. Paso amplio.
B40: 5 | C40: Elevación de talón sentado | D40: Sóleo | E40: 4 | F40: 15–20 | G40: 45s | H40: RPE 7 | I40: Sóleo. Rango completo. Pausa abajo para estiramiento máximo.
B41: 6 | C41: Elevación de talón de pie | D41: Gastrocnemio | E41: 3 | F41: 12–15 | G41: 45s | H41: RPE 7 | I41: Gastrocnemio. Pausa 1s arriba. No rebotar en el punto bajo.
B42: ↑ Progresión (doble progresión): completa el tope del rango de reps en TODAS las series → sube 2.5kg (comp.) o 1-2kg (accesorio). Vuelve al rango bajo con la nueva carga.
B44: DÍA 5 — FULL BODY (Énfasis glúteo)
B45: HIPERTROFIA · Segundo estímulo completo · RPE 7
B46: # | C46: Ejercicio | D46: Músculo | E46: Series | F46: Reps | G46: Descanso | H46: RPE | I46: Nota técnica / Carga
B47: 1 | C47: Hip thrust con barra | D47: Glúteo mayor | E47: 4 | F47: 10–15 | G47: 75s | H47: RPE 7–8 | I47: Tercer estímulo glúteo. Peso moderado. Pausa 2s. Alta contracción.
...

Sheet 📈 PROGRESIÓN
B2: PROGRESIÓN CIENTÍFICA — HIPERTROFIA
B3: Basado en: Israetel (2019) · ACSM (2009) · Colquhoun et al. (2017)
B5: JERARQUÍA DE ENTRENAMIENTO (de mayor a menor impacto)
B6: ① | C6: Periodización | D6: El sistema que organiza todo. Sin estructura, la sobrecarga no tiene dirección.
B7: ② | C7: Sobrecarga progresiva | D7: Primero: reducir descansos → más reps → más series → más volumen → al final: subir peso.
B8: ③ | C8: Volumen MEV–MAV | D8: Israetel 2019: series semanales dentro del rango efectivo por grupo muscular.
B9: ④ | C9: Técnica funcional | D9: Que el músculo objetivo trabaje. La anatomía es individual. No existe técnica 'universal perfecta'.
B10: ⑤ | C10: Técnica perfecta | D10: La menos importante. Inserción tendinosa y morfología ósea varían entre personas (Helms 2015).
B12: VOLUMEN CIENTÍFICO POR GRUPO MUSCULAR — Israetel, Hoffman & Case (2019)
B13: Grupo Muscular | C13: MEV | D13: MAV | E13: MRV | F13: Vol. asignado* | G13: Zona
B14: Pecho | C14: 8 | D14: 14 | E14: 20 | F14: =ROUND(IF('📋 DATOS'!C13="Menos de 6 meses",8,IF('📋 DATOS'!C13="6–24 meses",ROUND((8+14)/2,0),IF('📋 DATOS'!C13="2–4 años",14,ROUND((14+20)/2,0))))*'📋 DATOS'!E24,0) -> 0 | G14: =IF(F14<=8,"⚠ MEV",IF(F14<=14,"✓ Óptimo","⚡ Techo")) -> ⚠ MEV
B15: Espalda | C15: 10 | D15: 16 | E15: 25 | F15: =ROUND(IF('📋 DATOS'!C13="Menos de 6 meses",10,IF('📋 DATOS'!C13="6–24 meses",ROUND((10+16)/2,0),IF('📋 DATOS'!C13="2–4 años",16,ROUND((16+25)/2,0))))*'📋 DATOS'!E24,0) -> 0 | G15: =IF(F15<=10,"⚠ MEV",IF(F15<=16,"✓ Óptimo","⚡ Techo")) -> ⚠ MEV
B16: Hombros | C16: 8 | D16: 14 | E16: 20 | F16: =ROUND(IF('📋 DATOS'!C13="Menos de 6 meses",8,IF('📋 DATOS'!C13="6–24 meses",ROUND((8+14)/2,0),IF('📋 DATOS'!C13="2–4 años",14,ROUND((14+20)/2,0))))*'📋 DATOS'!E24,0) -> 0 | G16: =IF(F16<=8,"⚠ MEV",IF(F16<=14,"✓ Óptimo","⚡ Techo")) -> ⚠ MEV
B17: Bíceps | C17: 8 | D17: 12 | E17: 20 | F17: =ROUND(IF('📋 DATOS'!C13="Menos de 6 meses",8,IF('📋 DATOS'!C13="6–24 meses",ROUND((8+12)/2,0),IF('📋 DATOS'!C13="2–4 años",12,ROUND((12+20)/2,0))))*'📋 DATOS'!E24,0) -> 0 | G17: =IF(F17<=8,"⚠ MEV",IF(F17<=12,"✓ Óptimo","⚡ Techo")) -> ⚠ MEV
B18: Tríceps | C18: 6 | D18: 10 | E18: 18 | F18: =ROUND(IF('📋 DATOS'!C13="Menos de 6 meses",6,IF('📋 DATOS'!C13="6–24 meses",ROUND((6+10)/2,0),IF('📋 DATOS'!C13="2–4 años",10,ROUND((10+18)/2,0))))*'📋 DATOS'!E24,0) -> 0 | G18: =IF(F18<=6,"⚠ MEV",IF(F18<=10,"✓ Óptimo","⚡ Techo")) -> ⚠ MEV
B19: Cuádriceps | C19: 8 | D19: 14 | E19: 20 | F19: =ROUND(IF('📋 DATOS'!C13="Menos de 6 meses",8,IF('📋 DATOS'!C13="6–24 meses",ROUND((8+14)/2,0),IF('📋 DATOS'!C13="2–4 años",14,ROUND((14+20)/2,0))))*'📋 DATOS'!E24,0) -> 0 | G19: =IF(F19<=8,"⚠ MEV",IF(F19<=14,"✓ Óptimo","⚡ Techo")) -> ⚠ MEV
B20: Glúteos | C20: 10 | D20: 16 | E20: 22 | F20: =ROUND(IF('📋 DATOS'!C13="Menos de 6 meses",10,IF('📋 DATOS'!C13="6–24 meses",ROUND((10+16)/2,0),IF('📋 DATOS'!C13="2–4 años",16,ROUND((16+22)/2,0))))*'📋 DATOS'!E24,0) -> 0 | G20: =IF(F20<=10,"⚠ MEV",IF(F20<=16,"✓ Óptimo","⚡ Techo")) -> ⚠ MEV
B21: Core | C21: 6 | D21: 10 | E21: 16 | F21: =ROUND(IF('📋 DATOS'!C13="Menos de 6 meses",6,IF('📋 DATOS'!C13="6–24 meses",ROUND((6+10)/2,0),IF('📋 DATOS'!C13="2–4 años",10,ROUND((10+16)/2,0))))*'📋 DATOS'!E24,0) -> 0 | G21: =IF(F21<=6,"⚠ MEV",IF(F21<=10,"✓ Óptimo","⚡ Techo")) -> ⚠ MEV
B22: Antebrazos | C22: 4 | D22: 8 | E22: 14 | F22: =ROUND(IF('📋 DATOS'!C13="Menos de 6 meses",4,IF('📋 DATOS'!C13="6–24 meses",ROUND((4+8)/2,0),IF('📋 DATOS'!C13="2–4 años",8,ROUND((8+14)/2,0))))*'📋 DATOS'!E24,0) -> 0 | G22: =IF(F22<=4,"⚠ MEV",IF(F22<=8,"✓ Óptimo","⚡ Techo")) -> ⚠ MEV
B23: Pantorrilla | C23: 8 | D23: 14 | E23: 20 | F23: =ROUND(IF('📋 DATOS'!C13="Menos de 6 meses",8,IF('📋 DATOS'!C13="6–24 meses",ROUND((8+14)/2,0),IF('📋 DATOS'!C13="2–4 años",14,ROUND((14+20)/2,0))))*'📋 DATOS'!E24,0) -> 0 | G23: =IF(F23<=8,"⚠ MEV",IF(F23<=14,"✓ Óptimo","⚡ Techo")) -> ⚠ MEV
B26: MODELO DE DOBLE PROGRESIÓN — ACSM Position Stand (2009)
B27: Paso 1 | C27: Define tu rango | D27: Ejemplo: 3 × 8–12. El rango bajo (8) = nueva carga. El rango alto (12) = cuando subes carga.
B28: Paso 2 | C28: Trabaja dentro del rango | D28: Haces 3×10, 3×10, 3×10 → no subas todavía. Busca completar 3×12 en todas las series.
B29: Paso 3 | C29: Completa el tope del rango | D29: Cuando completas 3×12 en TODAS las series con buena forma → listo para subir peso.
B30: Paso 4 | C30: Sube la carga | D30: Añade 2.5kg en compuestos o 1–2kg en accesorios. No más.
B31: Paso 5 | C31: Vuelve al fondo | D31: Con la nueva carga, empiezas en 3×8 y repites el ciclo. Así funciona la progresión real.
B33: FALLO MUSCULAR — Cuándo sí y cuándo no (Schoenfeld et al. 2021)
B34: Principiante | C34: Nunca al fallo | D34: El SNC no está preparado. El riesgo de lesión supera el beneficio. RIR 3–4 siempre.
B35: Intermedio | C35: Solo en accesorios | D35: Llegar al fallo en jalón, curl, laterales: útil. En sentadilla o peso muerto: innecesario y peligroso.
B36: Avanzado | C36: Estratégicamente | D36: Fallo en accesorios de las últimas series. NUNCA en compuestos pesados. RIR 0–1 en aislamiento.
B37: SIEMPRE | C37: Técnica limpia primero | D37: El músculo no sabe cuánto pesa la barra. Sabe cuánta tensión recibe. Técnica funcional > peso máximo.
B40: ESCALA RPE — Rate of Perceived Exertion (qué significa cada color)
B41: RPE 6 | C41: Muy fácil — 4+ reps en el tanque | D41: Calentamiento, técnica, deload
B42: RPE 7 | C42: Moderado — 3 reps en el tanque | D42: Accesorios, principiantes
B43: RPE 8 | C43: Desafiante — 2 reps en el tanque | D43: Compuestos intermedios e hípertrofia
B44: RPE 9 | C44: Difícil — 1 rep en el tanque | D44: Compuestos avanzados, fuerza
B45: RPE 10 | C45: Al fallo — 0 reps en el tanque | D45: Solo accesorios estratégicamente

Sheet 🫁 RESPIRACIÓN + KEGEL
B2: RESPIRACIÓN CON CARGAS + SUELO PÉLVICO
B3: Protocolo clínico validado · Para hombres y mujeres · Fisioterapia del suelo pélvico
B5: ¿QUÉ ES EL SUELO PÉLVICO Y POR QUÉ ENTRENARLO?
B6: 4 funciones del suelo pélvico:
B7: ① SOPORTE — sostiene órganos internos y previene prolapsos ② CONTINENCIA — urinaria y fecal ③ ESTABILIZACIÓN — estática (sentado) y dinámica (movimiento, deporte) ④ SEXUAL — función eréctil y orgásmica
B8: Conexión con otros músculos:
B9: El suelo pélvico NO trabaja aislado. Está conectado con: diafragma · musculatura abdominal · glúteos · columna lumbar · musculatura profunda tónica. Todos trabajan en sinergia durante el ejercicio.
B10: ¿Cómo identificarlo?
B11: PARA CONTRAER EL SUELO PÉLVICO: imagina que estás conteniendo la orina, el canal vaginal/anal y cerrando el ano simultáneamente. La contracción debe sentirse como una elevación interna, NO como un empuje hacia afuera/abajo.
B12: Hipertrofia del suelo pélvico:
B13: Con Kegel lo que buscamos es hipertrofiar el suelo pélvico como se hipertrofian los glúteos o el cuádriceps. No es solo 'apretarlo' — es desarrollar masa muscular, densidad y resistencia en ese tejido.
B15: PROTOCOLO KEGEL ESTANDARIZADO — Bø et al. (2015) · Neurourology and Urodynamics
B16: Elemento | C16: Descripción detallada | D16: Errores comunes
B17: FASE 1 — Contracción mantenida | C17: Contrae el suelo pélvico al MÁXIMO posible. Mantén durante 6 segundos. La contracción va ligada a la EXHALACIÓN. Debes sentir que el suelo pélvico ASCIENDE (sube), no que empuja hacia abajo. Al terminar los 6s, INHALA y relaja completamente. | D17: Contener la respiración. Sentir que empuja hacia afuera. Contraer solo superficialmente. No exhalar durante la contracción.
B18: FASE 2 — Pulsos de contracción | C18: Inmediatamente después de la fase 1: realiza 4 pulsos rápidos de CONTRACCIÓN–RELAJACIÓN. Cada contracción = exhalación. Cada relajación = inhalación. Cada pulso al MÁXIMO de contracción posible en ese momento. | D18: Hacer los pulsos superficialmente. No llegar al máximo de contracción en cada pulso. No asociar cada contracción a la exhalación.
B19: SERIES Y POSICIONES | C19: Repetir el ejercicio completo (Fase 1 + Fase 2) = 1 repetición. Completar 8 repeticiones en cada posición: · Sentado · Parado · En cuclillas · Acostado Total: 4 posiciones × 8 reps = 32 repeticiones por sesión. | D19: Saltar posiciones. Hacer menos de 8 reps. No variar posiciones. Pensar que una sola posición es suficiente.
B20: FRECUENCIA | C20: DIARIO. Absolutamente todos los días. Da igual la hora del día. Da igual si es en ayunas o no. La consistencia diaria es el factor más importante del protocolo. La mejora en incontinencia y fortalecimiento ocurre con práctica diaria sostenida. | D20: Hacerlo solo cuando te acuerdas. Saltarse días. Pensar que 3 veces por semana es suficiente. El protocolo estandarizado requiere diario.
B21: RESPIRACIÓN EN KEGEL | C21: Cada contracción del suelo pélvico está ligada a la EXHALACIÓN. Cuando exhalas, el diafragma sube y el suelo pélvico también sube y se contrae. Cuando inhalas, ambos descienden y se relajan. Este patrón es fisiológicamente natural y es el que hay que entrenar conscientemente. | D21: Contraer al inhalar. Retener la respiración. No coordinar respiración con contracción. Hacer apnea durante los pulsos.
B22: SUPERVISIÓN RECOMENDADA | C22: Este protocolo debe ser guiado al menos una vez por semana por un fisioterapeuta especializado en suelo pélvico. Si no tienes acceso, el protocolo estandarizado produce mejoras significativas por sí solo, especialmente en incontinencia urinaria y fortalecimiento preventivo. | D22: Seguir protocolos de redes sociales sin estructura (contracción a ritmo de música, mil repeticiones sin objetivo, vacums abdominales — estos NO funcionan para hipertrofia del suelo pélvico).
B24: RESPIRACIÓN CON CARGAS — Para hombres y mujeres en el gym
B25: Tipo de carga | C25: Técnica respiratoria | D25: Ejemplos prácticos
B26: CARGAS BAJAS / MODERADAS (Accesorios, técnica, calentamiento) | C26: Respiración natural adaptada: · INHALAR en la fase de menor esfuerzo (excéntrica: bajar, alargar) · EXHALAR en la fase de mayor esfuerzo (concéntrica: subir, empujar) El suelo pélvico y core se activan automáticamente con la respiración correcta. No necesitas activarlos conscientemente. | D26: Curl de bíceps: inhala al bajar, exhala al subir. Extensión de tríceps: inhala al doblar, exhala al extender. Laterales: inhala al bajar, exhala al subir. Cualquier accesorio de hipertrofia normal.
B27: CARGAS ALTAS / MÁXIMAS (Compuestos pesados, 1–6 reps) | C27: Maniobra de Valsalva + NAC Perineal: ① Inhala profundo llenando el abdomen ② Valsalva: cierra la glotis (no entra ni sale aire) ③ NAC Perineal: contrae suelo pélvico elevando el perineo ④ Bracing: contrae el abdomen (como si fuera a recibir un golpe) ⑤ Mantén las 4 contracciones durante TODO el movimiento ⑥ Exhala al finalizar el recorrido completo | D27: Sentadilla pesada: inhala → Valsalva → contrae SP y abdomen → baja → sube → exhala al terminar. Peso muerto: toma la barra → inhala → Valsalva → SP y bracing → jala → exhala en lockout. Hip thrust pesado: inhala → SP → bracing → sube → exhala al bajar completamente.
B28: CONEXIÓN DIAFRAGMA — SUELO PÉLVICO (Fisiología normal durante el ejercicio) | C28: En respiración natural: · Al INHALAR: diafragma baja, abdomen se expande, suelo pélvico desciende (resiste activamente) · Al EXHALAR: diafragma sube, abdomen se contrae, suelo pélvico asciende y se activa En esfuerzo físico (correr, levantar, saltar): la presión intraabdominal aumenta. El suelo pélvico debe aumentar su tono ANTES de que llegue esa presión. Por eso es crítico entrenarlo. | D28: Este mecanismo explica por qué la gente con suelo pélvico débil pierde orina al correr, saltar o toser: la presión supera la capacidad del suelo pélvico de resistirla. Con entrenamiento Kegel diario + técnica respiratoria correcta, este mecanismo se vuelve automático y protege durante el ejercicio.
B30: RESUMEN — QUÉ HACER EN CADA EJERCICIO
B31: Accesorio ligero → Inhala excéntrica / Exhala concéntrica · Compuesto pesado → Valsalva + SP + Bracing · Kegel → Exhala al contraer, Inhala al relajar

Sheet 🔄 MOVILIDAD
B2: MOVILIDAD Y SERIES DE APROXIMACIÓN
B3: Preparación del SNC y articulaciones antes del entrenamiento · Behm & Chaouachi (2011, Scand. J. Med. Sci. Sports)
B5: ¿POR QUÉ MOVILIDAD ACTIVA ANTES DE ENTRENAR?
B6: El estiramiento ESTÁTICO antes del entrenamiento reduce la fuerza hasta un 5.4% (Behm & Chaouachi, 2011). El calentamiento DINÁMICO la mantiene o mejora. El objetivo no es flexibilidad pasiva sino movilidad activa: rango de movimiento con control muscular. El SNC necesita activarse específicamente para el ejercicio — una caminata en cinta NO es suficiente.
B8: RUTINA DE MOVILIDAD GENERAL — 8–12 MIN (TODOS LOS DÍAS DE ENTRENAMIENTO)
B9: Ejercicio | C9: Zona | D9: Dosis | E9: Ejecución correcta
B10: Rotaciones de cuello | C10: Columna cervical | D10: 5 círculos c/sentido | E10: Lento. Solo el peso de la cabeza. NUNCA forzar. Sin dolor.
B11: Rotaciones de hombros | C11: Glenohumeral | D11: 10 círculos F/R | E11: Amplitud máxima. Progresiva. Ambos brazos.
B12: Apertura torácica con brazos | C12: Columna torácica / pecho | D12: 10 reps | E12: Abrir los brazos. Exhalar al abrir. Pecho al frente.
B13: Rotaciones torácicas | C13: Columna torácica | D13: 8 por lado | E13: Cuadrupedia. Codo al techo. Cadera quieta.
B14: Movilidad de cadera 90/90 | C14: Cadera / rotadores | D14: 5 transiciones/lado | E14: Cambiar de posición 90/90. Espalda erguida. Sin dolor.
B15: Apertura de cadera en estocada | C15: Flexor cadera / glúteo | D15: 8 por lado | E15: Rodilla trasera en suelo. Cadera hacia adelante.
B16: Círculos de cadera de pie | C16: Articulación coxofemoral | D16: 8 círculos c/sentido | E16: Manos en cadera. Círculos amplios. Rodilla ligeramente flex.
B17: Movilidad de tobillos | C17: Tobillo / sóleo | D17: 10 por lado | E17: Apoyado en pared. Rodilla hacia adelante sobre el pie.
B18: Cat-cow | C18: Columna completa | D18: 10 reps | E18: Cuadrupedia. Inhala al extender, exhala al flexionar. Lento.
B19: Puente de glúteo — activación | C19: Glúteo / cadena post. | D19: 15 reps | E19: Pausa 2s arriba. Activar glúteo conscientemente.
B21: MOVILIDAD ESPECÍFICA POR DÍA
B22: Día | C22: Zona extra | D22: Ejercicios adicionales
B23: Push / Pecho / Hombros | C23: Hombros | D23: Rotación interna+externa con banda · Dislocaciones con palo · Apertura pectoral en marco · 2×10 cada uno
B24: Pull / Espalda | C24: Escápulas | D24: Retracción-protracción en barra · Suspensión pasiva · Círculos escapulares · 2×10
B25: Piernas / Glúteo | C25: Cadera profunda | D25: 90/90 en suelo · Frog stretch · Estocada con rotación · World's greatest stretch · 2×8/lado
B26: Full Upper | C26: Tren superior completo | D26: Combinar hombros + escapular + torácica · 5–8 min
B27: Full Body / Piernas+Brazos | C27: Completo | D27: Todos los generales · 10 min completos
B29: SERIES DE APROXIMACIÓN — CÓMO Y POR QUÉ
B30: Las series de aproximación preparan el patrón neuromuscular específico del ejercicio. NO son cardio. Son ensayos con carga progresiva para que el SNC active las unidades motoras correctas ANTES de la carga de trabajo. Resultado: más fuerza disponible, mejor técnica desde la serie 1, menor riesgo de lesión.
B31: Serie | C31: % del peso de trabajo | D31: Reps | E31: Objetivo | F31: Descanso
B32: Calentamiento 1 | C32: 40–50% | D32: 10–12 reps | E32: Activar el patrón. Sin esfuerzo. Solo movimiento. | F32: 30s
B33: Calentamiento 2 | C33: 60–65% | D33: 6–8 reps | E33: Sentir el ejercicio. RPE 4–5. Técnica perfecta. | F33: 45s
B34: Aproximación 1 | C34: 75–80% | D34: 4–5 reps | E34: Preparar el SNC. RPE 6. Ya debe sentirse el peso. | F34: 60s
B35: Aproximación 2 (si necesario) | C35: 87–90% | D35: 2–3 reps | E35: Solo ejercicios muy pesados (>80%RM). RPE 7–8. | F35: 90s
B36: ▶ Serie de trabajo 1 | C36: 100% peso de trabajo | D36: Reps objetivo | E36: SNC activado. Listo para rendir al máximo. | F36: Descanso completo
B38: REGLA CLAVE: Las aproximaciones NUNCA cansan. Si llegas fatigado a la primera serie de trabajo, fueron demasiado pesadas o con demasiadas reps. El objetivo es activar, no fatigar.

Sheet 💪 CORE + TRAPECIOS + MUÑECAS
B2: CORE · TRAPECIOS · FUERZA DE MUÑECAS
B3: Músculos frecuentemente ignorados con alto impacto en rendimiento, postura y prevención de lesiones
B5: ① CORE — FUNDAMENTOS, VOLUMEN Y EJERCICIOS
B6: El core NO es el abdomen. Es toda la musculatura que conecta el tren superior con el inferior. 3 funciones en hipertrofia: TRANSFERENCIA (transmite fuerza del pie a la barra), PROTECCIÓN (distribuye carga espinal en compuestos), CONTROL (posición bajo carga máxima). SIEMPRE al final — un core fatigado reduce la estabilidad en sentadilla, peso muerto e hip thrust.
B8: VOLUMEN DE CORE — Israetel (2019)
B9: Variable | C9: Principiante | D9: Intermedio | E9: Avanzado | F9: Nota científica
B10: Series/semana | C10: 6–8 series | D10: 8–12 series | E10: 10–16 series | F10: MEV=6 · MAV=10 · MRV=16 (Israetel 2019)
B11: Frecuencia | C11: 2×/semana | D11: 3×/semana | E11: 3–4×/semana | F11: El core se recupera rápido — mayor frecuencia viable
B12: Cuándo | C12: AL FINAL siempre | D12: AL FINAL siempre | E12: AL FINAL siempre | F12: Si se fatiga antes: pierde función en compuestos
B13: RPE | C13: RPE 7 | D13: RPE 7–8 | E13: RPE 8 | F13: El fallo en core es contraproducente — RIR 1–2
B14: Progresión | C14: Más segundos / más reps | D14: Más series / variantes | E14: Carga añadida + variantes avanzadas | F14: Doble progresión igual que cualquier grupo
B16: EJERCICIOS DE CORE — PROTOCOLO COMPLETO
B17: Ejercicio | C17: Músculo | D17: Series×Reps | E17: RPE / Nivel | F17: Instrucción de ejecución
B18: Crunch en polea (parado o apoyado) | C18: Recto abdominal | D18: 3 × 12–15 | E18: RPE 7–8 · Princ+ | F18: Cuerda o barra en polea alta. Parado o apoyado en banco inclinado. EXHALAR al flexionar — suelo pélvico activo. Contracción máxima abajo. No usar el peso de los brazos. La polea da tensión constante — superior al crunch en suelo.
B19: Press Pallof | C19: Core anti-rotación | D19: 3 × 30–45s/lado | E19: RPE 7 · Princ+ | F19: Polea a altura del pecho. Lateralmente. Brazos extendidos al frente. Clave: NO ROTAR. Resistir la fuerza lateral de la polea. Exhalar controlado. Replica la función real del core en cualquier ejercicio compuesto.
B20: Rueda abdominal (ab wheel) | C20: Core completo / serrato | D20: 3 × 8–12 | E20: RPE 8 · Avanzado | F20: Desde rodillas (principiante) o de pie (avanzado). Salir lento controlando la extensión — cadera NO debe caer en ningún punto. Volver contrayendo el abdomen. Si la cadera cae: regresa a la versión de rodillas hasta tener fuerza suficiente.
B21: Elevación de piernas colgado + elevación de cadera | C21: Core / hip flexors / oblicuos | D21: 3 × 8–15 | E21: RPE 8 · Avanzado | F21: Colgado de la barra. NO solo subir piernas — elevar la CADERA al final (retroversión pélvica). Eso activa el recto abdominal en su rango completo. Sin balanceo. Bajar controlado. Variante principiante: rodillas flexionadas o en paralelas.
B23: INTEGRACIÓN DEL CORE EN CADA RUTINA
B24: Hombre 5 días | C24: Día 1 Push: 2 ejercicios core al final · Día 3 Piernas: 1 ejercicio · Día 6 Piernas+Brazos: 2 ejercicios → 5–6 series en 3 días
B25: Hombre 3 días | C25: Día 1 Cuerpo completo: 2 ejercicios · Día 3 Superior: 1 · Día 5 Inferior: 2 → 5 series en 3 días
B26: Mujer 5 días | C26: Día 2 Tren superior: 2 ejercicios · Día 4 Pierna cuádriceps: 1 · Día 5 Full body: 2 → 5 series en 3 días
B27: ⚠ Regla universal | C27: SIEMPRE al final. NUNCA antes de compuestos. Core fatigado = menos estabilidad en sentadilla, peso muerto e hip thrust.
B29: ② TRAPECIOS — ISOMÉTRICOS Y DINÁMICOS
B30: Los trapecios son críticos para la estabilidad escapular y el rendimiento en todo el tren superior. La combinación de isométricos (tiempo bajo tensión) y dinámicos (rango completo) produce mayor adaptación que solo uno de los dos métodos (Schoenfeld & Grgic, 2019). Volumen recomendado: 6–10 series semanales. Integrar al final del día de Pull o Upper.
B32: Ejercicio | C32: Músculo | D32: Series×Reps | E32: RPE | F32: Método | G32: Instrucción
B33: Elevación de hombros — isométrica | C33: Trapecio superior | D33: 3 × 20–30s | E33: RPE 8 | F33: Isométrico | G33: Subir hombros al máximo. MANTENER la contracción. Tensión máxima durante todo el tiempo. Bajar controlado. Progresa +5s cada semana hasta 45s.
B34: Elevación de hombros — dinámica | C34: Trapecio superior | D34: 3 × 10–15 | E34: RPE 7–8 | F34: Dinámico | G34: Subir hombros al máximo. Pausa 1–2s arriba (contracción voluntaria máxima). Bajar controlado 3s. NO rotar los hombros — movimiento vertical puro.
B35: Elevación de hombros con barra (carga alta) | C35: Trapecio superior | D35: 4 × 6–8 | E35: RPE 8–9 | F35: Fuerza | G35: Mayor carga que mancuernas. Agarre pronado o neutro. Pausa 1s arriba. Escápulas activas. Progresión: doble progresión.
B36: Encogimiento unilateral con mancuerna | C36: Trapecio unilateral | D36: 3 × 12–15/lado | E36: RPE 7 | F36: Dinámico | G36: Un lado a la vez. Mayor rango y mejor conexión neuromuscular. Pausa 1s arriba.
B37: 5s isométrico + 5 reps dinámicas (protocolo avanzado) | C37: Trapecio — máxima activación | D37: 3 series | E37: RPE 8 | F37: Combinado | G37: Sube y mantén 5s isométrico → sin bajar, haz 5 reps dinámicas rápidas → baja. = 1 serie. Maximiza resistencia y reclutamiento de fibras rápidas simultáneamente.
B39: ③ FUERZA DE MUÑECAS Y ANTEBRAZOS — KETTLEBELLS Y MÁS
B40: La fuerza de agarre y muñecas es el eslabón débil más ignorado. Limita directamente jalones, remos, peso muerto y toda tracción. Los tendones de la muñeca tardan 2–4 MESES en adaptarse (menor vascularización). Las pesas rusas son especialmente efectivas porque el centro de masa desplazado crea mayor demanda de control de muñeca en cada movimiento.
B42: Ejercicio | C42: Músculos | D42: Series×Reps | E42: RPE | F42: Instrucción de ejecución
B43: Paseo del granjero (mancuerna / barra / kettlebell) | C43: Antebrazos / agarre / trapecio / core | D43: 3 × 30–40m o 45–60s | E43: RPE 7–8 | F43: Hombros activos (no dejar caer). Espalda recta. Ritmo constante. El kettlebell añade inestabilidad que exige más control de muñeca. Progresa: más peso o más distancia/tiempo.
B44: Swing de kettlebell | C44: Glúteo / isquiotibiales / core / agarre | D44: 4 × 15–20 | E44: RPE 7–8 | F44: MOVIMIENTO DE CADERA, no de sentadilla. Empuje explosivo de glúteo. Muñeca neutra — no doblar nunca. Kettlebell hasta altura de hombros máximo. El agarre trabaja isométricamente en cada rep.
B45: Kettlebell clean + press | C45: Hombro / agarre / muñeca / core | D45: 3 × 6–8/lado | E45: RPE 8 | F45: Clean: limpiar la KB desde el swing a posición rack (muñeca girada, KB en antebrazo). Press: empujar overhead. La transición clean→rack trabaja extensamente muñeca y antebrazo.
B46: Kettlebell bottoms-up press | C46: Estabilización muñeca / hombro | D46: 3 × 5–8/lado | E46: RPE 8 | F46: Sostener la KB con el fondo hacia arriba. La inestabilidad obliga a la muñeca y el hombro a trabajar activamente para mantener equilibrio. Peso muy ligero. Alta demanda neural. Excelente para hombro y control de muñeca.
B47: Flexores de muñeca en polea | C47: Flexores del antebrazo | D47: 3 × 15–20 | E47: RPE 7 | F47: Antebrazo apoyado en banco. Solo mover la muñeca. Rango completo: extensión completa abajo, flexión completa arriba. Peso ligero — enfocarse en rango y contracción.
B48: Extensores de muñeca en polea | C48: Extensores del antebrazo | D48: 3 × 15–20 | E48: RPE 7 | F48: Palma hacia abajo. Extensión completa arriba. Bajar controlado. SIEMPRE entrenar en par con flexores — el desequilibrio causa epicondilitis (codo de tenista).
B49: Rotaciones de muñeca con mancuerna | C49: Pronadores / supinadores | D49: 2 × 15 c/dirección | E49: RPE 6 | F49: Mancuerna ligera (2–5kg). Antebrazo horizontal. Rotar completamente en ambas direcciones. Activación y movilidad articular. Ideal para el calentamiento de muñeca.
...
